Workbook

Sheet pasos
A1: 1 | B1: guardar el archivo con el nombre del equipo analizado
A2: 2 | B2: escribir los resultados de TODOS los partidos jugados por el equipo bajo análisis en la hoja "datos"
A3: 3 | B3: filtrar los juegos como local
A4: 4 | B4: copiar las columnas A-J de los datos filtrados, y pegarlos en las columnas A-J en la hoja "desglose"
A5: 5 | B5: filtrar los juegos como visitante
A6: 6 | B6: copiar las columnas A-J de los datos filtrados, y pegarlos en las columnas L-U en la hoja "desglose"
A7: 7 | B7: quitar los filtros
A8: 8 | B8: revisar los resultados en la hoja "sumario de distribuciones elegidas"
A9: 9 | B9: guardar el libro
A10: 10 | B10: enviar el libro a través del grupo UNITED 26

Sheet datos
A1: Fecha | B1: Ëlo-Runyan | C1: Equipo | D1: Local/Vistiante | E1: Resultado | F1: GF | G1: GA | H1: Ëlo rival | I1: Rival | J1: Tipo | K1: K | L1: G | M1: p | O1: type | P1: K
A2: 45008 | B2: 2145 | C2: Argentina | D2: Home | E2: W | F2: 2 | G2: 0 | H2: 1640 | I2: Panama | J2: Friendly | K2: =+VLOOKUP(J2,$O$2:$P$6,2,0) -> 20 | L2: =+IF(ABS(F2-G2)<=1,1,IF(ABS(F2-G2)=2,1.5,(11+ABS(F2-G2))/8)) -> 1.5 | M2: =(1+10^((H2-B2)/400))^-1 -> 0.94819206 | O2: World cup | P2: 60
A3: 45013 | B3: =+B2+K2*L2*(IF(E2="W",1,IF(E2="D",0.5,0))-M2) -> 2146.5542 | C3: Argentina | D3: Home | E3: W | F3: 7 | G3: 0 | H3: 1350 | I3: Curazao | J3: Friendly | K3: =+VLOOKUP(J3,$O$2:$P$6,2,0) -> 20 | L3: =+IF(ABS(F3-G3)<=1,1,IF(ABS(F3-G3)=2,1.5,(11+ABS(F3-G3))/8)) -> 2.25 | M3: =(1+10^((H3-B3)/400))^-1 -> 0.98990266 | O3: Continental | P3: 50
A4: 45092 | B4: =+B3+K3*L3*(IF(E3="W",1,IF(E3="D",0.5,0))-M3) -> 2147.0086 | C4: Argentina | D4: Home | E4: W | F4: 2 | G4: 0 | H4: 1772 | I4: Australia | J4: Friendly | K4: =+VLOOKUP(J4,$O$2:$P$6,2,0) -> 20 | L4: =+IF(ABS(F4-G4)<=1,1,IF(ABS(F4-G4)=2,1.5,(11+ABS(F4-G4))/8)) -> 1.5 | M4: =(1+10^((H4-B4)/400))^-1 -> 0.89648111 | O4: Qualifier | P4: 40
A5: 45096 | B5: =+B4+K4*L4*(IF(E4="W",1,IF(E4="D",0.5,0))-M4) -> 2150.1142 | C5: Argentina | D5: Away | E5: W | F5: 2 | G5: 0 | H5: 1287 | I5: Indonesia | J5: Friendly | K5: =+VLOOKUP(J5,$O$2:$P$6,2,0) -> 20 | L5: =+IF(ABS(F5-G5)<=1,1,IF(ABS(F5-G5)=2,1.5,(11+ABS(F5-G5))/8)) -> 1.5 | M5: =(1+10^((H5-B5)/400))^-1 -> 0.99309434 | O5: Other | P5: 30
A6: 45176 | B6: =+B5+K5*L5*(IF(E5="W",1,IF(E5="D",0.5,0))-M5) -> 2150.3214 | C6: Argentina | D6: Home | E6: W | F6: 1 | G6: 0 | H6: 1849 | I6: Ecuador | J6: Qualifier | K6: =+VLOOKUP(J6,$O$2:$P$6,2,0) -> 40 | L6: =+IF(ABS(F6-G6)<=1,1,IF(ABS(F6-G6)=2,1.5,(11+ABS(F6-G6))/8)) -> 1 | M6: =(1+10^((H6-B6)/400))^-1 -> 0.84999287 | O6: Friendly | P6: 20
A7: 45181 | B7: =+B6+K6*L6*(IF(E6="W",1,IF(E6="D",0.5,0))-M6) -> 2156.3216 | C7: Argentina | D7: Away | E7: W | F7: 3 | G7: 0 | H7: 1596 | I7: Bolivia | J7: Qualifier | K7: =+VLOOKUP(J7,$O$2:$P$6,2,0) -> 40 | L7: =+IF(ABS(F7-G7)<=1,1,IF(ABS(F7-G7)=2,1.5,(11+ABS(F7-G7))/8)) -> 1.75 | M7: =(1+10^((H7-B7)/400))^-1 -> 0.96178161
A8: 45211 | B8: =+B7+K7*L7*(IF(E7="W",1,IF(E7="D",0.5,0))-M7) -> 2158.9969 | C8: Argentina | D8: Home | E8: W | F8: 1 | G8: 0 | H8: 1703 | I8: Paraguay | J8: Qualifier | K8: =+VLOOKUP(J8,$O$2:$P$6,2,0) -> 40 | L8: =+IF(ABS(F8-G8)<=1,1,IF(ABS(F8-G8)=2,1.5,(11+ABS(F8-G8))/8)) -> 1 | M8: =(1+10^((H8-B8)/400))^-1 -> 0.93244886
A9: 45216 | B9: =+B8+K8*L8*(IF(E8="W",1,IF(E8="D",0.5,0))-M8) -> 2161.699 | C9: Argentina | D9: Away | E9: W | F9: 2 | G9: 0 | H9: 1786 | I9: Peru | J9: Qualifier | K9: =+VLOOKUP(J9,$O$2:$P$6,2,0) -> 40 | L9: =+IF(ABS(F9-G9)<=1,1,IF(ABS(F9-G9)=2,1.5,(11+ABS(F9-G9))/8)) -> 1.5 | M9: =(1+10^((H9-B9)/400))^-1 -> 0.89684933
A10: 45246 | B10: =+B9+K9*L9*(IF(E9="W",1,IF(E9="D",0.5,0))-M9) -> 2167.888 | C10: Argentina | D10: Home | E10: L | F10: 0 | G10: 2 | H10: 2002 | I10: Uruguay | J10: Qualifier | K10: =+VLOOKUP(J10,$O$2:$P$6,2,0) -> 40 | L10: =+IF(ABS(F10-G10)<=1,1,IF(ABS(F10-G10)=2,1.5,(11+ABS(F10-G10))/8)) -> 1.5 | M10: =(1+10^((H10-B10)/400))^-1 -> 0.72210519
A11: 45251 | B11: =+B10+K10*L10*(IF(E10="W",1,IF(E10="D",0.5,0))-M10) -> 2124.5617 | C11: Argentina | D11: Away | E11: W | F11: 1 | G11: 0 | H11: 2011 | I11: Brasil | J11: Qualifier | K11: =+VLOOKUP(J11,$O$2:$P$6,2,0) -> 40 | L11: =+IF(ABS(F11-G11)<=1,1,IF(ABS(F11-G11)=2,1.5,(11+ABS(F11-G11))/8)) -> 1 | M11: =(1+10^((H11-B11)/400))^-1 -> 0.65784685
A12: 45373 | B12: =+B11+K11*L11*(IF(E11="W",1,IF(E11="D",0.5,0))-M11) -> 2138.2478 | C12: Argentina | D12: Home | E12: W | F12: 3 | G12: 0 | H12: 1394 | I12: El Salvador | J12: Friendly | K12: =+VLOOKUP(J12,$O$2:$P$6,2,0) -> 20 | L12: =+IF(ABS(F12-G12)<=1,1,IF(ABS(F12-G12)=2,1.5,(11+ABS(F12-G12))/8)) -> 1.75 | M12: =(1+10^((H12-B12)/400))^-1 -> 0.98640326
A13: 45377 | B13: =+B12+K12*L12*(IF(E12="W",1,IF(E12="D",0.5,0))-M12) -> 2138.7237 | C13: Argentina | D13: Home | E13: W | F13: 3 | G13: 1 | H13: 1605 | I13: Costa Rica | J13: Friendly | K13: =+VLOOKUP(J13,$O$2:$P$6,2,0) -> 20 | L13: =+IF(ABS(F13-G13)<=1,1,IF(ABS(F13-G13)=2,1.5,(11+ABS(F13-G13))/8)) -> 1.5 | M13: =(1+10^((H13-B13)/400))^-1 -> 0.95573814
A14: 45452 | B14: =+B13+K13*L13*(IF(E13="W",1,IF(E13="D",0.5,0))-M13) -> 2140.0516 | C14: Argentina | D14: Home | E14: W | F14: 1 | G14: 0 | H14: 1869 | I14: Ecuador | J14: Friendly | K14: =+VLOOKUP(J14,$O$2:$P$6,2,0) -> 20 | L14: =+IF(ABS(F14-G14)<=1,1,IF(ABS(F14-G14)=2,1.5,(11+ABS(F14-G14))/8)) -> 1 | M14: =(1+10^((H14-B14)/400))^-1 -> 0.82639615
A15: 45457 | B15: =+B14+K14*L14*(IF(E14="W",1,IF(E14="D",0.5,0))-M14) -> 2143.5236 | C15: Argentina | D15: Home | E15: W | F15: 4 | G15: 1 | H15: 1486 | I15: Guatemala | J15: Friendly | K15: =+VLOOKUP(J15,$O$2:$P$6,2,0) -> 20 | L15: =+IF(ABS(F15-G15)<=1,1,IF(ABS(F15-G15)=2,1.5,(11+ABS(F15-G15))/8)) -> 1.75 | M15: =(1+10^((H15-B15)/400))^-1 -> 0.9777956
A16: 45463 | B16: =+B15+K15*L15*(IF(E15="W",1,IF(E15="D",0.5,0))-M15) -> 2144.3008 | C16: Argentina | D16: Home | E16: W | F16: 2 | G16: 0 | H16: 1714 | I16: Canada | J16: Continental | K16: =+VLOOKUP(J16,$O$2:$P$6,2,0) -> 50 | L16: =+IF(ABS(F16-G16)<=1,1,IF(ABS(F16-G16)=2,1.5,(11+ABS(F16-G16))/8)) -> 1.5 | M16: =(1+10^((H16-B16)/400))^-1 -> 0.92251437
A17: 45468 | B17: =+B16+K16*L16*(IF(E16="W",1,IF(E16="D",0.5,0))-M16) -> 2150.1122 | C17: Argentina | D17: Home | E17: W | F17: 1 | G17: 0 | H17: 1722 | I17: Chile | J17: Continental | K17: =+VLOOKUP(J17,$O$2:$P$6,2,0) -> 50 | L17: =+IF(ABS(F17-G17)<=1,1,IF(ABS(F17-G17)=2,1.5,(11+ABS(F17-G17))/8)) -> 1 | M17: =(1+10^((H17-B17)/400))^-1 -> 0.92160901
A18: 45472 | B18: =+B17+K17*L17*(IF(E17="W",1,IF(E17="D",0.5,0))-M17) -> 2154.0318 | C18: Argentina | D18: Home | E18: W | F18: 2 | G18: 0 | H18: 1709 | I18: Peru | J18: Continental | K18: =+VLOOKUP(J18,$O$2:$P$6,2,0) -> 50 | L18: =+IF(ABS(F18-G18)<=1,1,IF(ABS(F18-G18)=2,1.5,(11+ABS(F18-G18))/8)) -> 1.5 | M18: =(1+10^((H18-B18)/400))^-1 -> 0.92836285
... A38: 46112 | B38: =+B37+K37*L37*(IF(E37="W",1,IF(E37="D",0.5,0))-M37) -> 2111.1542 | C38: Argentina | D38: Home | E38: W | F38: 5 | G38: 0 | H38: 1370 | I38: Zambia | J38: Friendly | K38: =+VLOOKUP(J38,$O$2:$P$6,2,0) -> 20 | L38: =+IF(ABS(F38-G38)<=1,1,IF(ABS(F38-G38)=2,1.5,(11+ABS(F38-G38))/8)) -> 2 | M38: =(1+10^((H38-B38)/400))^-1 -> 0.98616233
A39: 46179 | B39: 2114 | C39: Argentina | D39: Home | E39: W | F39: 2 | G39: 0 | H39: 1570 | I39: Honduras | J39: Friendly | K39: =+VLOOKUP(J39,$O$2:$P$6,2,0) -> 20 | L39: =+IF(ABS(F39-G39)<=1,1,IF(ABS(F39-G39)=2,1.5,(11+ABS(F39-G39))/8)) -> 1.5 | M39: =(1+10^((H39-B39)/400))^-1 -> 0.95817418
A40: 46182 | B40: 2115 | C40: Argentina | D40: Home | E40: W | F40: 3 | G40: 0 | H40: 1568 | I40: Iceland | J40: Friendly | K40: =+VLOOKUP(J40,$O$2:$P$6,2,0) -> 20 | L40: =+IF(ABS(F40-G40)<=1,1,IF(ABS(F40-G40)=2,1.5,(11+ABS(F40-G40))/8)) -> 1.75 | M40: =(1+10^((H40-B40)/400))^-1 -> 0.95886083
C41: Argentina | D41: Home | E41: W | F41: 3 | G41: 0 | I41: Algeria | J41: World Cup
C42: Argentina | D42: Home | E42: W | F42: 2 | G42: 0 | I42: Austria | J42: World Cup
C43: Argentina | D43: Away | E43: W | F43: 3 | G43: 1 | I43: Jordan | J43: World Cup
C44: Argentina | D44: Home | E44: W | F44: 3 | G44: 2 | I44: Cape Verte | J44: World Cup
C45: Argentina | D45: Home | E45: W | F45: 3 | G45: 2 | I45: Egypt | J45: World Cup
C46: Argentina | D46: Home | E46: W | F46: 3 | G46: 1 | I46: Helvetia | J46: World Cup
C47: Argentina | D47: Away | E47: W | F47: 2 | G47: 1 | I47: England | J47: World Cup

Sheet desglose
A1: Fecha | B1: Ëlo-Runyan | C1: Equipo | D1: Local/Vistiante | E1: Resultado | F1: GF | G1: GA | H1: Ëlo rival | I1: Rival | J1: Tipo | L1: Fecha | M1: Ëlo-Runyan | N1: Equipo | O1: Local/Vistiante | P1: Resultado | Q1: GF | R1: GA | S1: Ëlo rival | T1: Rival | U1: Tipo
A2: 45008 | B2: 2145 | C2: Argentina | D2: Home | E2: W | F2: 2 | G2: 0 | H2: 1640 | I2: Panama | J2: Friendly | L2: 45096 | M2: 2150.1142 | N2: Argentina | O2: Away | P2: W | Q2: 2 | R2: 0 | S2: 1287 | T2: Indonesia | U2: Friendly
A3: 45013 | B3: 2146.5542 | C3: Argentina | D3: Home | E3: W | F3: 7 | G3: 0 | H3: 1350 | I3: Curazao | J3: Friendly | L3: 45181 | M3: 2156.3216 | N3: Argentina | O3: Away | P3: W | Q3: 3 | R3: 0 | S3: 1596 | T3: Bolivia | U3: Qualifier
A4: 45092 | B4: 2147.0086 | C4: Argentina | D4: Home | E4: W | F4: 2 | G4: 0 | H4: 1772 | I4: Australia | J4: Friendly | L4: 45216 | M4: 2161.699 | N4: Argentina | O4: Away | P4: W | Q4: 2 | R4: 0 | S4: 1786 | T4: Peru | U4: Qualifier
A5: 45176 | B5: 2150.3214 | C5: Argentina | D5: Home | E5: W | F5: 1 | G5: 0 | H5: 1849 | I5: Ecuador | J5: Qualifier | L5: 45251 | M5: 2124.5617 | N5: Argentina | O5: Away | P5: W | Q5: 1 | R5: 0 | S5: 2011 | T5: Brasil | U5: Qualifier
A6: 45211 | B6: 2158.9969 | C6: Argentina | D6: Home | E6: W | F6: 1 | G6: 0 | H6: 1703 | I6: Paraguay | J6: Qualifier | L6: 45545 | M6: 2172.1049 | N6: Argentina | O6: Away | P6: L | Q6: 1 | R6: 2 | S6: 2060 | T6: Colombia | U6: Qualifier
A7: 45246 | B7: 2167.888 | C7: Argentina | D7: Home | E7: L | F7: 0 | G7: 2 | H7: 2002 | I7: Uruguay | J7: Qualifier | L7: 45575 | M7: 2145.8666 | N7: Argentina | O7: Away | P7: D | Q7: 1 | R7: 1 | S7: 1783 | T7: Venezuela | U7: Qualifier
A8: 45373 | B8: 2138.2478 | C8: Argentina | D8: Home | E8: W | F8: 3 | G8: 0 | H8: 1394 | I8: El Salvador | J8: Friendly | L8: 45610 | M8: 2135.8255 | N8: Argentina | O8: Away | P8: L | Q8: 1 | R8: 2 | S8: 1776 | T8: Paraguay | U8: Qualifier
A9: 45377 | B9: 2138.7237 | C9: Argentina | D9: Home | E9: W | F9: 3 | G9: 1 | H9: 1605 | I9: Costa Rica | J9: Friendly | L9: 45737 | M9: 2104.373 | N9: Argentina | O9: Away | P9: W | Q9: 1 | R9: 0 | S9: 1931 | T9: Uruguay | U9: Qualifier
A10: 45452 | B10: 2140.0516 | C10: Argentina | D10: Home | E10: W | F10: 1 | G10: 0 | H10: 1869 | I10: Ecuador | J10: Friendly | L10: 45813 | M10: 2138.3246 | N10: Argentina | O10: Away | P10: W | Q10: 1 | R10: 0 | S10: 1717 | T10: Chile | U10: Qualifier
A11: 45457 | B11: 2143.5236 | C11: Argentina | D11: Home | E11: W | F11: 4 | G11: 1 | H11: 1486 | I11: Guatemala | J11: Friendly | L11: 45909 | M11: 2138.2293 | N11: Argentina | O11: Away | P11: L | Q11: 0 | R11: 1 | S11: 1934 | T11: Ecuador | U11: Qualifier
A12: 45463 | B12: 2144.3008 | C12: Argentina | D12: Home | E12: W | F12: 2 | G12: 0 | H12: 1714 | I12: Canada | J12: Continental | L12: 45975 | M12: 2109.7062 | N12: Argentina | O12: Away | P12: W | Q12: 2 | R12: 0 | S12: 1565 | T12: Angola | U12: Friendly
A13: 45468 | B13: 2150.1122 | C13: Argentina | D13: Home | E13: W | F13: 1 | G13: 0 | H13: 1722 | I13: Chile | J13: Continental | N13: Argentina | O13: Home | P13: W | Q13: 3 | R13: 0 | T13: Algeria | U13: World Cup
A14: 45472 | B14: 2154.0318 | C14: Argentina | D14: Home | E14: W | F14: 2 | G14: 0 | H14: 1709 | I14: Peru | J14: Continental | N14: Argentina | O14: Home | P14: W | Q14: 2 | R14: 0 | T14: Austria | U14: World Cup
A15: 45477 | B15: 2159.4046 | C15: Argentina | D15: Home | E15: D | F15: 1 | G15: 1 | H15: 1871 | I15: Ecuador | J15: Continental | N15: Argentina | O15: Away | P15: W | Q15: 3 | R15: 1 | T15: Jordan | U15: World Cup
A16: 45482 | B16: 2142.3914 | C16: Argentina | D16: Home | E16: W | F16: 2 | G16: 0 | H16: 1739 | I16: Canada | J16: Continental | N16: Argentina | O16: Home | P16: W | Q16: 3 | R16: 2 | T16: Cape Verte | U16: World Cup
A17: 45487 | B17: 2149.0895 | C17: Argentina | D17: Home | E17: W | F17: 1 | G17: 0 | H17: 2050 | I17: Colombia | J17: Continental | N17: Argentina | O17: Home | P17: W | Q17: 3 | R17: 2 | T17: Egypt | U17: World Cup
A18: 45540 | B18: 2167.1467 | C18: Argentina | D18: Home | E18: W | F18: 3 | G18: 0 | H18: 1720 | I18: Chile | J18: Qualifier | N18: Argentina | O18: Home | P18: W | Q18: 3 | R18: 1 | T18: Helvetia | U18: World Cup
A19: 45580 | B19: 2130.2741 | C19: Argentina | D19: Home | E19: W | F19: 6 | G19: 0 | H19: 1668 | I19: Bolivia | J19: Qualifier | N19: Argentina | O19: Away | P19: W | Q19: 2 | R19: 1 | T19: England | U19: World Cup
A20: 45615 | B20: 2100.3021 | C20: Argentina | D20: Home | E20: W | F20: 1 | G20: 0 | H20: 1722 | I20: Peru | J20: Qualifier
A21: 45741 | B21: 2115.1463 | C21: Argentina | D21: Home | E21: W | F21: 4 | G21: 1 | H21: 1993 | I21: Brasil | J21: Qualifier
A22: 45818 | B22: 2141.575 | C22: Argentina | D22: Home | E22: D | F22: 1 | G22: 1 | H22: 1950 | I22: Colombia | J22: Qualifier
A23: 45904 | B23: 2131.5437 | C23: Argentina | D23: Home | E23: W | F23: 3 | G23: 0 | H23: 1741 | I23: Venezuela | J23: Qualifier
A24: 45940 | B24: 2107.6628 | C24: Argentina | D24: Home | E24: W | F24: 1 | G24: 0 | H24: 1715 | I24: Venezuela | J24: Friendly
A25: 45944 | B25: 2109.552 | C25: Argentina | D25: Home | E25: W | F25: 6 | G25: 0 | H25: 1134 | I25: Puerto Rico | J25: Friendly
A26: 46108 | B26: 2110.9561 | C26: Argentina | D26: Home | E26: W | F26: 2 | G26: 1 | H26: 1311 | I26: Mauritania | J26: Friendly
A27: 46112 | B27: 2111.1542 | C27: Argentina | D27: Home | E27: W | F27: 5 | G27: 0 | H27: 1370 | I27: Zambia | J27: Friendly
A28: 46179 | B28: 2114 | C28: Argentina | D28: Home | E28: W | F28: 2 | G28: 0 | H28: 1570 | I28: Honduras | J28: Friendly
A29: 46182 | B29: 2115 | C29: Argentina | D29: Home | E29: W | F29: 3 | G29: 0 | H29: 1568 | I29: Iceland | J29: Friendly
C30: Argentina | D30: Home | E30: W | F30: 3 | G30: 0 | I30: Algeria | J30: World Cup
C31: Argentina | D31: Home | E31: W | F31: 2 | G31: 0 | I31: Austria | J31: World Cup
C32: Argentina | D32: Away | E32: W | F32: 3 | G32: 1 | I32: Jordan | J32: World Cup
C33: Argentina | D33: Home | E33: W | F33: 3 | G33: 2 | I33: Cape Verte | J33: World Cup
C34: Argentina | D34: Home | E34: W | F34: 3 | G34: 2 | I34: Egypt | J34: World Cup
C35: Argentina | D35: Home | E35: W | F35: 3 | G35: 1 | I35: Helvetia | J35: World Cup
C36: Argentina | D36: Away | E36: W | F36: 2 | G36: 1 | I36: England | J36: World Cup

Sheet estadísticos descriptivos
B1: GF-local | C1: GA-local | D1: GF-visitante | E1: GA-visitante
A2: no. Juegos | B2: =+COUNT(desglose!F:F) -> 35 | C2: =+COUNT(desglose!G:G) -> 35 | D2: =+COUNT(desglose!Q:Q) -> 18 | E2: =+COUNT(desglose!R:R) -> 18
A3: total goles | B3: =+SUM(desglose!F:F) -> 89 | C3: =+SUM(desglose!G:G) -> 15 | D3: =+SUM(desglose!Q:Q) -> 34 | E3: =+SUM(desglose!R:R) -> 13
A4: mínimo goles | B4: =+MIN(desglose!F:F) -> 0 | C4: =+MIN(desglose!G:G) -> 0 | D4: =+MIN(desglose!Q:Q) -> 0 | E4: =+MIN(desglose!R:R) -> 0
A5: máximo goles | B5: =+MAX(desglose!F:F) -> 7 | C5: =+MAX(desglose!G:G) -> 2 | D5: =+MAX(desglose!Q:Q) -> 3 | E5: =+MAX(desglose!R:R) -> 2
A6: promedio goles | B6: =AVERAGE(desglose!F:F) -> 2.5428571 | C6: =AVERAGE(desglose!G:G) -> 0.42857143 | D6: =AVERAGE(desglose!Q:Q) -> 1.8888889 | E6: =AVERAGE(desglose!R:R) -> 0.72222222
A7: varianza goles | B7: =STDEV(desglose!F:F)^2 -> 2.5495798 | C7: =STDEV(desglose!G:G)^2 -> 0.42857143 | D7: =STDEV(desglose!Q:Q)^2 -> 0.92810458 | E7: =STDEV(desglose!R:R)^2 -> 0.68300654
A8: diferencia relativa | B8: =+ABS(B6-B7)/MIN(B6:B7) -> 0.0026437541 | C8: =+ABS(C6-C7)/MIN(C6:C7) -> 1.2952602e-16 | D8: =+ABS(D6-D7)/MIN(D6:D7) -> 1.0352113 | E8: =+ABS(E6-E7)/MIN(E6:E7) -> 0.057416268

Sheet pruebas de bondad de ajuste
B1: OBSERVADOS | F1: POISSON | J1: Ji cuadradas | N1: BINOMIAL | R1: Ji cuadradas | V1: BINOMIAL NEGATIVA | Z1: Ji cuadradas | AD1: =+'estadísticos descriptivos'!B$6^2/('estadísticos descriptivos'!B$7-'estadísticos descriptivos'!B$6) -> 961.83571 | AE1: =+'estadísticos descriptivos'!C$6^2/('estadísticos descriptivos'!C$7-'estadísticos descriptivos'!C$6) -> -3.3087671e+15 | AF1: =+'estadísticos descriptivos'!D$6^2/('estadísticos descriptivos'!D$7-'estadísticos descriptivos'!D$6) -> -3.7135299 | AG1: =+'estadísticos descriptivos'!E$6^2/('estadísticos descriptivos'!E$7-'estadísticos descriptivos'!E$6) -> -13.300926
B2: LOCAL | D2: VISTANTE | F2: LOCAL | H2: VISTANTE | J2: LOCAL | L2: VISTANTE | N2: LOCAL | P2: VISTANTE | R2: LOCAL | T2: VISTANTE | V2: LOCAL | X2: VISTANTE | Z2: LOCAL | AB2: VISTANTE | AD2: =+'estadísticos descriptivos'!B$6/('estadísticos descriptivos'!B$7-'estadísticos descriptivos'!B$6) -> 378.25 | AE2: =+'estadísticos descriptivos'!C$6/('estadísticos descriptivos'!C$7-'estadísticos descriptivos'!C$6) -> -7.7204565e+15 | AF2: =+'estadísticos descriptivos'!D$6/('estadísticos descriptivos'!D$7-'estadísticos descriptivos'!D$6) -> -1.9659864 | AG2: =+'estadísticos descriptivos'!E$6/('estadísticos descriptivos'!E$7-'estadísticos descriptivos'!E$6) -> -18.416667
A3: goles | B3: GF-local | C3: GA-local | D3: GF-vsitante | E3: GA-vsitante | F3: GF-esperados-Poisson | G3: GA-esperados-Poisson | H3: GF-esperados-Poisson | I3: GF-esperados-Poisson | J3: =IF(_xlfn.CHISQ.DIST.RT(SUM(J4:J94),90-1)<=0.05,"rechazar","no rechazar") -> no rechazar | K3: =IF(_xlfn.CHISQ.DIST.RT(SUM(K4:K94),90-1)<=0.05,"rechazar","no rechazar") -> no rechazar | L3: =IF(_xlfn.CHISQ.DIST.RT(SUM(L4:L94),90-1)<=0.05,"rechazar","no rechazar") -> no rechazar | M3: =IF(_xlfn.CHISQ.DIST.RT(SUM(M4:M94),90-1)<=0.05,"rechazar","no rechazar") -> no rechazar | N3: GF-esperados-bin | O3: GA-esperados-bin | P3: GF-esperados-bin | Q3: GF-esperados-bon | R3: =IF(_xlfn.CHISQ.DIST.RT(SUM(R4:R94),90-1)<=0.05,"rechazar","no rechazar") -> no rechazar | S3: =IF(_xlfn.CHISQ.DIST.RT(SUM(S4:S94),90-1)<=0.05,"rechazar","no rechazar") -> no rechazar | T3: =IF(_xlfn.CHISQ.DIST.RT(SUM(T4:T94),90-1)<=0.05,"rechazar","no rechazar") -> no rechazar | U3: =IF(_xlfn.CHISQ.DIST.RT(SUM(U4:U94),90-1)<=0.05,"rechazar","no rechazar") -> no rechazar | V3: GF-esperados-BinNeg | W3: GA-esperados-BinNeg | X3: GF-esperados-BinNeg | Y3: GF-esperados-BinNeg | Z3: =IF(_xlfn.CHISQ.DIST.RT(SUM(Z4:Z94),90-1)<=0.05,"rechazar","no rechazar") -> no rechazar | AA3: =IF(_xlfn.CHISQ.DIST.RT(SUM(AA4:AA94),90-1)<=0.05,"rechazar","no rechazar") -> no rechazar | AB3: =IF(_xlfn.CHISQ.DIST.RT(SUM(AB4:AB94),90-1)<=0.05,"rechazar","no rechazar") -> no rechazar | AC3: =IF(_xlfn.CHISQ.DIST.RT(SUM(AC4:AC94),90-1)<=0.05,"rechazar","no rechazar") -> no rechazar
A4: 0 | B4: =+COUNTIF(desglose!F:F,'pruebas de bondad de ajuste'!$A4) -> 1 | C4: =+COUNTIF(desglose!G:G,'pruebas de bondad de ajuste'!$A4) -> 23 | D4: =+COUNTIF(desglose!Q:Q,'pruebas de bondad de ajuste'!$A4) -> 1 | E4: =+COUNTIF(desglose!R:R,'pruebas de bondad de ajuste'!$A4) -> 9 | F4: =+_xlfn.POISSON.DIST($A4,'estadísticos descriptivos'!B$6,0)*'estadísticos descriptivos'!B$2 -> 2.7524486 | G4: =+_xlfn.POISSON.DIST($A4,'estadísticos descriptivos'!C$6,0)*'estadísticos descriptivos'!C$2 -> 22.800367 | H4: =+_xlfn.POISSON.DIST($A4,'estadísticos descriptivos'!D$6,0)*'estadísticos descriptivos'!D$2 -> 2.7223157 | I4: =+_xlfn.POISSON.DIST($A4,'estadísticos descriptivos'!E$6,0)*'estadísticos descriptivos'!E$2 -> 8.7420921 | J4: =+($B4-F4)^2/F4 -> 1.1157615 | K4: =+($C4-G4)^2/G4 -> 0.0017479249 | L4: =+($D4-H4)^2/H4 -> 1.08965 | M4: =+($E4-I4)^2/I4 -> 0.0076087584 | N4: =BINOMDIST($A4,90,'estadísticos descriptivos'!B$6/90,0)*'estadísticos descriptivos'!B$2 -> 2.6534925 | O4: =BINOMDIST($A4,90,'estadísticos descriptivos'!C$6/90,0)*'estadísticos descriptivos'!C$2 -> 22.777039 | P4: =BINOMDIST($A4,90,'estadísticos descriptivos'!D$6/90,0)*'estadísticos descriptivos'!D$2 -> 2.6681342 | Q4: =BINOMDIST($A4,90,'estadísticos descriptivos'!E$6/90,0)*'estadísticos descriptivos'!E$2 -> 8.71666 | R4: =+($B4-N4)^2/N4 -> 1.0303543 | S4: =+($C4-O4)^2/O4 -> 0.0021825286 | T4: =+($D4-P4)^2/P4 -> 1.0429279 | U4: =+($E4-Q4)^2/Q4 -> 0.0092101299 | V4: =+(AD$2/(1+AD$2))^AD$1*'estadísticos descriptivos'!B$2 -> 2.7616998 | W4: =+(AE$2/(1+AE$2))^AE$1*'estadísticos descriptivos'!C$2 -> 16.787829 | X4: =+(AF$2/(1+AF$2))^AF$1*'estadísticos descriptivos'!D$2 -> 1.2860028 | Y4: =+(AG$2/(1+AG$2))^AG$1*'estadísticos descriptivos'!E$2 -> 8.5660069 | Z4: =+($B4-V4)^2/V4 -> 1.1237956 | AA4: =+($C4-W4)^2/W4 -> 2.2987524 | AB4: =+($D4-X4)^2/X4 -> 0.063606089 | AC4: =+($E4-Y4)^2/Y4 -> 0.021988075
A5: =1+A4 -> 1 | B5: =+COUNTIF(desglose!F:F,'pruebas de bondad de ajuste'!$A5) -> 9 | C5: =+COUNTIF(desglose!G:G,'pruebas de bondad de ajuste'!$A5) -> 9 | D5: =+COUNTIF(desglose!Q:Q,'pruebas de bondad de ajuste'!$A5) -> 6 | E5: =+COUNTIF(desglose!R:R,'pruebas de bondad de ajuste'!$A5)/'estadísticos descriptivos'!E$2 -> 0.27777778 | F5: =+_xlfn.POISSON.DIST($A5,'estadísticos descriptivos'!B$6,0)*'estadísticos descriptivos'!B$2 -> 6.9990836 | G5: =+_xlfn.POISSON.DIST($A5,'estadísticos descriptivos'!C$6,0)*'estadísticos descriptivos'!C$2 -> 9.7715859 | H5: =+_xlfn.POISSON.DIST($A5,'estadísticos descriptivos'!D$6,0)*'estadísticos descriptivos'!D$2 -> 5.1421518 | I5: =+_xlfn.POISSON.DIST($A5,'estadísticos descriptivos'!E$6,0)*'estadísticos descriptivos'!E$2 -> 6.3137332 | J5: =+($B5-F5)^2/F5 -> 0.57202723 | K5: =+($C5-G5)^2/G5 -> 0.060926113 | L5: =+($D5-H5)^2/H5 -> 0.14311197 | M5: =+($E5-I5)^2/I5 -> 5.7703987 | N5: =BINOMDIST($A5,90,'estadísticos descriptivos'!B$6/90,0)*'estadísticos descriptivos'!B$2 -> 6.9436377 | O5: =BINOMDIST($A5,90,'estadísticos descriptivos'!C$6/90,0)*'estadísticos descriptivos'!C$2 -> 9.8082944 | P5: =BINOMDIST($A5,90,'estadísticos descriptivos'!D$6/90,0)*'estadísticos descriptivos'!D$2 -> 5.1478503 | Q5: =BINOMDIST($A5,90,'estadísticos descriptivos'!E$6/90,0)*'estadísticos descriptivos'!E$2 -> 6.3462926 | R5: =+($B5-N5)^2/N5 -> 0.60899287 | S5: =+($C5-O5)^2/O5 -> 0.066610948 | T5: =+($D5-P5)^2/P5 -> 0.14106065 | U5: =+($E5-Q5)^2/Q5 -> 5.8028954 | V5: =+($A5+AD$1)/(($A5+1)*(1+AD$2))*V4 -> 3.5056865 | W5: =+($A5+AE$1)/(($A5+1)*(1+AE$2))*W4 -> 3.597392 | X5: =+($A5+AF$1)/(($A5+1)*(1+AF$2))*X4 -> 1.8062403 | Y5: =+($A5+AG$1)/(($A5+1)*(1+AG$2))*Y4 -> 3.0249708 | Z5: =+($B5-V5)^2/V5 -> 8.6110044 | AA5: =+($C5-W5)^2/W5 -> 8.1137037 | AB5: =+($D5-X5)^2/X5 -> 9.7371436 | AC5: =+($E5-Y5)^2/Y5 -> 2.4949231
A6: =1+A5 -> 2 | B6: =+COUNTIF(desglose!F:F,'pruebas de bondad de ajuste'!$A6) -> 9 | C6: =+COUNTIF(desglose!G:G,'pruebas de bondad de ajuste'!$A6) -> 3 | D6: =+COUNTIF(desglose!Q:Q,'pruebas de bondad de ajuste'!$A6)/'estadísticos descriptivos'!D$2 -> 0.27777778 | E6: =+COUNTIF(desglose!R:R,'pruebas de bondad de ajuste'!$A6)/'estadísticos descriptivos'!E$2 -> 0.22222222 | F6: =+_xlfn.POISSON.DIST($A6,'estadísticos descriptivos'!B$6,0)*'estadísticos descriptivos'!B$2 -> 8.8988349 | G6: =+_xlfn.POISSON.DIST($A6,'estadísticos descriptivos'!C$6,0)*'estadísticos descriptivos'!C$2 -> 2.0939113 | H6: =+_xlfn.POISSON.DIST($A6,'estadísticos descriptivos'!D$6,0)*'estadísticos descriptivos'!D$2 -> 4.8564767 | I6: =+_xlfn.POISSON.DIST($A6,'estadísticos descriptivos'!E$6,0)*'estadísticos descriptivos'!E$2 -> 2.2799592 | J6: =+($B6-F6)^2/F6 -> 0.0011500813 | K6: =+($C6-G6)^2/G6 -> 0.39208768 | L6: =+($D6-H6)^2/H6 -> 4.3168093 | M6: =+($E6-I6)^2/I6 -> 1.8571742 | N6: =BINOMDIST($A6,90,'estadísticos descriptivos'!B$6/90,0)*'estadísticos descriptivos'!B$2 -> 8.9840827 | O6: =BINOMDIST($A6,90,'estadísticos descriptivos'!C$6/90,0)*'estadísticos descriptivos'!C$2 -> 2.0883689 | P6: =BINOMDIST($A6,90,'estadísticos descriptivos'!D$6/90,0)*'estadísticos descriptivos'!D$2 -> 4.9109064 | Q6: =BINOMDIST($A6,90,'estadísticos descriptivos'!E$6/90,0)*'estadísticos descriptivos'!E$2 -> 2.2845863 | R6: =+($B6-N6)^2/N6 -> 2.8200997e-05 | S6: =+($C6-O6)^2/O6 -> 0.39795233 | T6: =+($D6-P6)^2/P6 -> 4.3710629 | U6: =+($E6-Q6)^2/Q6 -> 1.8617575 | V6: =+($A6+AD$1)/(($A6+1)*(1+AD$2))*V5 -> 2.9698139 | W6: =+($A6+AE$1)/(($A6+1)*(1+AE$2))*W5 -> 0.51391315 | X6: =+($A6+AF$1)/(($A6+1)*(1+AF$2))*X5 -> 1.068009 | Y6: =+($A6+AG$1)/(($A6+1)*(1+AG$2))*Y5 -> 0.65425782 | Z6: =+($B6-V6)^2/V6 -> 12.24425 | AA6: =+($C6-W6)^2/W6 -> 12.0266 | AB6: =+($D6-X6)^2/X6 -> 0.58470053 | AC6: =+($E6-Y6)^2/Y6 -> 0.28529236
A7: =1+A6 -> 3 | B7: =+COUNTIF(desglose!F:F,'pruebas de bondad de ajuste'!$A7) -> 10 | C7: =+COUNTIF(desglose!G:G,'pruebas de bondad de ajuste'!$A7) -> 0 | D7: =+COUNTIF(desglose!Q:Q,'pruebas de bondad de ajuste'!$A7)/'estadísticos descriptivos'!D$2 -> 0.33333333 | E7: =+COUNTIF(desglose!R:R,'pruebas de bondad de ajuste'!$A7)/'estadísticos descriptivos'!E$2 -> 0 | F7: =+_xlfn.POISSON.DIST($A7,'estadísticos descriptivos'!B$6,0)*'estadísticos descriptivos'!B$2 -> 7.5428219 | G7: =+_xlfn.POISSON.DIST($A7,'estadísticos descriptivos'!C$6,0)*'estadísticos descriptivos'!C$2 -> 0.29913018 | H7: =+_xlfn.POISSON.DIST($A7,'estadísticos descriptivos'!D$6,0)*'estadísticos descriptivos'!D$2 -> 3.0577816 | I7: =+_xlfn.POISSON.DIST($A7,'estadísticos descriptivos'!E$6,0)*'estadísticos descriptivos'!E$2 -> 0.54887907 | J7: =+($B7-F7)^2/F7 -> 0.80045957 | K7: =+($C7-G7)^2/G7 -> 0.29913018 | L7: =+($D7-H7)^2/H7 -> 2.4274521 | M7: =+($E7-I7)^2/I7 -> 0.54887907 | N7: =BINOMDIST($A7,90,'estadísticos descriptivos'!B$6/90,0)*'estadísticos descriptivos'!B$2 -> 7.6623474 | O7: =BINOMDIST($A7,90,'estadísticos descriptivos'!C$6/90,0)*'estadísticos descriptivos'!C$2 -> 0.29310441 | P7: =BINOMDIST($A7,90,'estadísticos descriptivos'!D$6/90,0)*'estadísticos descriptivos'!D$2 -> 3.088153 | Q7: =BINOMDIST($A7,90,'estadísticos descriptivos'!E$6/90,0)*'estadísticos descriptivos'!E$2 -> 0.5421213 | R7: =+($B7-N7)^2/N7 -> 0.7131783 | S7: =+($C7-O7)^2/O7 -> 0.29310441 | T7: =+($D7-P7)^2/P7 -> 2.4574661 | U7: =+($E7-Q7)^2/Q7 -> 0.5421213 | V7: =+($A7+AD$1)/(($A7+1)*(1+AD$2))*V6 -> 1.8888481 | W7: =+($A7+AE$1)/(($A7+1)*(1+AE$2))*W6 -> 0.055062123 | X7: =+($A7+AF$1)/(($A7+1)*(1+AF$2))*X6 -> 0.19722233 | Y7: =+($A7+AG$1)/(($A7+1)*(1+AG$2))*Y6 -> 0.096738679 | Z7: =+($B7-V7)^2/V7 -> 34.831168 | AA7: =+($C7-W7)^2/W7 -> 0.055062123 | AB7: =+($D7-X7)^2/X7 -> 0.093935643 | AC7: =+($E7-Y7)^2/Y7 -> 0.096738679
A8: =1+A7 -> 4 | B8: =+COUNTIF(desglose!F:F,'pruebas de bondad de ajuste'!$A8) -> 2 | C8: =+COUNTIF(desglose!G:G,'pruebas de bondad de ajuste'!$A8) -> 0 | D8: =+COUNTIF(desglose!Q:Q,'pruebas de bondad de ajuste'!$A8)/'estadísticos descriptivos'!D$2 -> 0 | E8: =+COUNTIF(desglose!R:R,'pruebas de bondad de ajuste'!$A8)/'estadísticos descriptivos'!E$2 -> 0 | F8: =+_xlfn.POISSON.DIST($A8,'estadísticos descriptivos'!B$6,0)*'estadísticos descriptivos'!B$2 -> 4.7950797 | G8: =+_xlfn.POISSON.DIST($A8,'estadísticos descriptivos'!C$6,0)*'estadísticos descriptivos'!C$2 -> 0.032049662 | H8: =+_xlfn.POISSON.DIST($A8,'estadísticos descriptivos'!D$6,0)*'estadísticos descriptivos'!D$2 -> 1.4439524 | I8: =+_xlfn.POISSON.DIST($A8,'estadísticos descriptivos'!E$6,0)*'estadísticos descriptivos'!E$2 -> 0.099103165 | J8: =+($B8-F8)^2/F8 -> 1.6292681 | K8: =+($C8-G8)^2/G8 -> 0.032049662 | L8: =+($D8-H8)^2/H8 -> 1.4439524 | M8: =+($E8-I8)^2/I8 -> 0.099103165 | N8: =BINOMDIST($A8,90,'estadísticos descriptivos'!B$6/90,0)*'estadísticos descriptivos'!B$2 -> 4.8456024 | O8: =BINOMDIST($A8,90,'estadísticos descriptivos'!C$6/90,0)*'estadísticos descriptivos'!C$2 -> 0.030502492 | P8: =BINOMDIST($A8,90,'estadísticos descriptivos'!D$6/90,0)*'estadísticos descriptivos'!D$2 -> 1.4399049 | Q8: =BINOMDIST($A8,90,'estadísticos descriptivos'!E$6/90,0)*'estadísticos descriptivos'!E$2 -> 0.095385686 | R8: =+($B8-N8)^2/N8 -> 1.6710931 | S8: =+($C8-O8)^2/O8 -> 0.030502492 | T8: =+($D8-P8)^2/P8 -> 1.4399049 | U8: =+($E8-Q8)^2/Q8 -> 0.095385686 | V8: =+($A8+AD$1)/(($A8+1)*(1+AD$2))*V7 -> 0.96206563 | W8: =+($A8+AE$1)/(($A8+1)*(1+AE$2))*W7 -> 0.0047196105 | X8: =+($A8+AF$1)/(($A8+1)*(1+AF$2))*X7 -> -0.011697537 | Y8: =+($A8+AG$1)/(($A8+1)*(1+AG$2))*Y7 -> 0.010332164 | Z8: =+($B8-V8)^2/V8 -> 1.1197862 | AA8: =+($C8-W8)^2/W8 -> 0.0047196105 | AB8: =+($D8-X8)^2/X8 -> -0.011697537 | AC8: =+($E8-Y8)^2/Y8 -> 0.010332164
A9: =1+A8 -> 5 | B9: =+COUNTIF(desglose!F:F,'pruebas de bondad de ajuste'!$A9) -> 1 | C9: =+COUNTIF(desglose!G:G,'pruebas de bondad de ajuste'!$A9) -> 0 | D9: =+COUNTIF(desglose!Q:Q,'pruebas de bondad de ajuste'!$A9)/'estadísticos descriptivos'!D$2 -> 0 | E9: =+COUNTIF(desglose!R:R,'pruebas de bondad de ajuste'!$A9)/'estadísticos descriptivos'!E$2 -> 0 | F9: =+_xlfn.POISSON.DIST($A9,'estadísticos descriptivos'!B$6,0)*'estadísticos descriptivos'!B$2 -> 2.4386405 | G9: =+_xlfn.POISSON.DIST($A9,'estadísticos descriptivos'!C$6,0)*'estadísticos descriptivos'!C$2 -> 0.0027471139 | H9: =+_xlfn.POISSON.DIST($A9,'estadísticos descriptivos'!D$6,0)*'estadísticos descriptivos'!D$2 -> 0.54549315 | I9: =+_xlfn.POISSON.DIST($A9,'estadísticos descriptivos'!E$6,0)*'estadísticos descriptivos'!E$2 -> 0.014314902 | J9: =+($B9-F9)^2/F9 -> 0.84870505 | K9: =+($C9-G9)^2/G9 -> 0.0027471139 | L9: =+($D9-H9)^2/H9 -> 0.54549315 | M9: =+($E9-I9)^2/I9 -> 0.014314902 | N9: =BINOMDIST($A9,90,'estadísticos descriptivos'!B$6/90,0)*'estadísticos descriptivos'!B$2 -> 2.4232761 | O9: =BINOMDIST($A9,90,'estadísticos descriptivos'!C$6/90,0)*'estadísticos descriptivos'!C$2 -> 0.0025102529 | P9: =BINOMDIST($A9,90,'estadísticos descriptivos'!D$6/90,0)*'estadísticos descriptivos'!D$2 -> 0.53093087 | Q9: =BINOMDIST($A9,90,'estadísticos descriptivos'!E$6/90,0)*'estadísticos descriptivos'!E$2 -> 0.013272084 | R9: =+($B9-N9)^2/N9 -> 0.83594059 | S9: =+($C9-O9)^2/O9 -> 0.0025102529 | T9: =+($D9-P9)^2/P9 -> 0.53093087 | U9: =+($E9-Q9)^2/Q9 -> 0.013272084 | V9: =+($A9+AD$1)/(($A9+1)*(1+AD$2))*V8 -> 0.40877144 | W9: =+($A9+AE$1)/(($A9+1)*(1+AE$2))*W8 -> 0.00033711504 | X9: =+($A9+AF$1)/(($A9+1)*(1+AF$2))*X8 -> 0.0025964017 | Y9: =+($A9+AG$1)/(($A9+1)*(1+AG$2))*Y8 -> 0.00082073233 | Z9: =+($B9-V9)^2/V9 -> 0.85512631 | AA9: =+($C9-W9)^2/W9 -> 0.00033711504 | AB9: =+($D9-X9)^2/X9 -> 0.0025964017 | AC9: =+($E9-Y9)^2/Y9 -> 0.00082073233
A10: =1+A9 -> 6 | B10: =+COUNTIF(desglose!F:F,'pruebas de bondad de ajuste'!$A10) -> 2 | C10: =+COUNTIF(desglose!G:G,'pruebas de bondad de ajuste'!$A10) -> 0 | D10: =+COUNTIF(desglose!Q:Q,'pruebas de bondad de ajuste'!$A10)/'estadísticos descriptivos'!D$2 -> 0 | E10: =+COUNTIF(desglose!R:R,'pruebas de bondad de ajuste'!$A10)/'estadísticos descriptivos'!E$2 -> 0 | F10: =+_xlfn.POISSON.DIST($A10,'estadísticos descriptivos'!B$6,0)*'estadísticos descriptivos'!B$2 -> 1.0335191 | G10: =+_xlfn.POISSON.DIST($A10,'estadísticos descriptivos'!C$6,0)*'estadísticos descriptivos'!C$2 -> 0.00019622242 | H10: =+_xlfn.POISSON.DIST($A10,'estadísticos descriptivos'!D$6,0)*'estadísticos descriptivos'!D$2 -> 0.17172932 | I10: =+_xlfn.POISSON.DIST($A10,'estadísticos descriptivos'!E$6,0)*'estadísticos descriptivos'!E$2 -> 0.00172309 | J10: =+($B10-F10)^2/F10 -> 0.90379114 | K10: =+($C10-G10)^2/G10 -> 0.00019622242 | L10: =+($D10-H10)^2/H10 -> 0.17172932 | M10: =+($E10-I10)^2/I10 -> 0.00172309 | N10: =BINOMDIST($A10,90,'estadísticos descriptivos'!B$6/90,0)*'estadísticos descriptivos'!B$2 -> 0.99815331 | O10: =BINOMDIST($A10,90,'estadísticos descriptivos'!C$6/90,0)*'estadísticos descriptivos'!C$2 -> 0.00017015271 | P10: =BINOMDIST($A10,90,'estadísticos descriptivos'!D$6/90,0)*'estadísticos descriptivos'!D$2 -> 0.16124319 | Q10: =BINOMDIST($A10,90,'estadísticos descriptivos'!E$6/90,0)*'estadísticos descriptivos'!E$2 -> 0.0015210177 | R10: =+($B10-N10)^2/N10 -> 1.0055537 | S10: =+($C10-O10)^2/O10 -> 0.00017015271 | T10: =+($D10-P10)^2/P10 -> 0.16124319 | U10: =+($E10-Q10)^2/Q10 -> 0.0015210177 | V10: =+($A10+AD$1)/(($A10+1)*(1+AD$2))*V9 -> 0.1490248 | W10: =+($A10+AE$1)/(($A10+1)*(1+AE$2))*W9 -> 2.0639696e-05 | X10: =+($A10+AF$1)/(($A10+1)*(1+AF$2))*X9 -> -0.00087794714 | Y10: =+($A10+AG$1)/(($A10+1)*(1+AG$2))*Y9 -> 4.9149195e-05 | Z10: =+($B10-V10)^2/V10 -> 22.990194 | AA10: =+($C10-W10)^2/W10 -> 2.0639696e-05 | AB10: =+($D10-X10)^2/X10 -> -0.00087794714 | AC10: =+($E10-Y10)^2/Y10 -> 4.9149195e-05
A11: =1+A10 -> 7 | B11: =+COUNTIF(desglose!F:F,'pruebas de bondad de ajuste'!$A11) -> 1 | C11: =+COUNTIF(desglose!G:G,'pruebas de bondad de ajuste'!$A11) -> 0 | D11: =+COUNTIF(desglose!Q:Q,'pruebas de bondad de ajuste'!$A11)/'estadísticos descriptivos'!D$2 -> 0 | E11: =+COUNTIF(desglose!R:R,'pruebas de bondad de ajuste'!$A11)/'estadísticos descriptivos'!E$2 -> 0 | F11: =+_xlfn.POISSON.DIST($A11,'estadísticos descriptivos'!B$6,0)*'estadísticos descriptivos'!B$2 -> 0.37544162 | G11: =+_xlfn.POISSON.DIST($A11,'estadísticos descriptivos'!C$6,0)*'estadísticos descriptivos'!C$2 -> 1.2013618e-05 | H11: =+_xlfn.POISSON.DIST($A11,'estadísticos descriptivos'!D$6,0)*'estadísticos descriptivos'!D$2 -> 0.046339659 | I11: =+_xlfn.POISSON.DIST($A11,'estadísticos descriptivos'!E$6,0)*'estadísticos descriptivos'!E$2 -> 0.00017777913 | J11: =+($B11-F11)^2/F11 -> 1.0389716 | K11: =+($C11-G11)^2/G11 -> 1.2013618e-05 | L11: =+($D11-H11)^2/H11 -> 0.046339659 | M11: =+($E11-I11)^2/I11 -> 0.00017777913 | N11: =BINOMDIST($A11,90,'estadísticos descriptivos'!B$6/90,0)*'estadísticos descriptivos'!B$2 -> 0.34826127 | O11: =BINOMDIST($A11,90,'estadísticos descriptivos'!C$6/90,0)*'estadísticos descriptivos'!C$2 -> 9.7695336e-06 | P11: =BINOMDIST($A11,90,'estadísticos descriptivos'!D$6/90,0)*'estadísticos descriptivos'!D$2 -> 0.041479964 | Q11: =BINOMDIST($A11,90,'estadísticos descriptivos'!E$6/90,0)*'estadísticos descriptivos'!E$2 -> 0.00014765325 | R11: =+($B11-N11)^2/N11 -> 1.2196687 | S11: =+($C11-O11)^2/O11 -> 9.7695336e-06 | T11: =+($D11-P11)^2/P11 -> 0.041479964 | U11: =+($E11-Q11)^2/Q11 -> 0.00014765325 | V11: =+($A11+AD$1)/(($A11+1)*(1+AD$2))*V10 -> 0.047587525 | W11: =+($A11+AE$1)/(($A11+1)*(1+AE$2))*W10 -> 1.105698e-06 | X11: =+($A11+AF$1)/(($A11+1)*(1+AF$2))*X10 -> 0.00037336797 | Y11: =+($A11+AG$1)/(($A11+1)*(1+AG$2))*Y10 -> 2.2226227e-06 | Z11: =+($B11-V11)^2/V11 -> 19.061498 | AA11: =+($C11-W11)^2/W11 -> 1.105698e-06 | AB11: =+($D11-X11)^2/X11 -> 0.00037336797 | AC11: =+($E11-Y11)^2/Y11 -> 2.2226227e-06
A12: =1+A11 -> 8 | B12: =+COUNTIF(desglose!F:F,'pruebas de bondad de ajuste'!$A12) -> 0 | C12: =+COUNTIF(desglose!G:G,'pruebas de bondad de ajuste'!$A12) -> 0 | D12: =+COUNTIF(desglose!Q:Q,'pruebas de bondad de ajuste'!$A12)/'estadísticos descriptivos'!D$2 -> 0 | E12: =+COUNTIF(desglose!R:R,'pruebas de bondad de ajuste'!$A12)/'estadísticos descriptivos'!E$2 -> 0 | F12: =+_xlfn.POISSON.DIST($A12,'estadísticos descriptivos'!B$6,0)*'estadísticos descriptivos'!B$2 -> 0.1193368 | G12: =+_xlfn.POISSON.DIST($A12,'estadísticos descriptivos'!C$6,0)*'estadísticos descriptivos'!C$2 -> 6.4358666e-07 | H12: =+_xlfn.POISSON.DIST($A12,'estadísticos descriptivos'!D$6,0)*'estadísticos descriptivos'!D$2 -> 0.010941308 | I12: =+_xlfn.POISSON.DIST($A12,'estadísticos descriptivos'!E$6,0)*'estadísticos descriptivos'!E$2 -> 1.6049505e-05 | J12: =+($B12-F12)^2/F12 -> 0.1193368 | K12: =+($C12-G12)^2/G12 -> 6.4358666e-07 | L12: =+($D12-H12)^2/H12 -> 0.010941308 | M12: =+($E12-I12)^2/I12 -> 1.6049505e-05 | N12: =BINOMDIST($A12,90,'estadísticos descriptivos'!B$6/90,0)*'estadísticos descriptivos'!B$2 -> 0.10505578 | O12: =BINOMDIST($A12,90,'estadísticos descriptivos'!C$6/90,0)*'estadísticos descriptivos'!C$2 -> 4.8497087e-07 | P12: =BINOMDIST($A12,90,'estadísticos descriptivos'!D$6/90,0)*'estadísticos descriptivos'!D$2 -> 0.0092257612 | Q12: =BINOMDIST($A12,90,'estadísticos descriptivos'!E$6/90,0)*'estadísticos descriptivos'!E$2 -> 1.239249e-05 | R12: =+($B12-N12)^2/N12 -> 0.10505578 | S12: =+($C12-O12)^2/O12 -> 4.8497087e-07 | T12: =+($D12-P12)^2/P12 -> 0.0092257612 | U12: =+($E12-Q12)^2/Q12 -> 1.239249e-05 | V12: =+($A12+AD$1)/(($A12+1)*(1+AD$2))*V11 -> 0.013521448 | W12: =+($A12+AE$1)/(($A12+1)*(1+AE$2))*W11 -> 5.2652286e-08 | X12: =+($A12+AF$1)/(($A12+1)*(1+AF$2))*X11 -> -0.0001840871 | Y12: =+($A12+AG$1)/(($A12+1)*(1+AG$2))*Y11 -> 7.5164009e-08 | Z12: =+($B12-V12)^2/V12 -> 0.013521448 | AA12: =+($C12-W12)^2/W12 -> 5.2652286e-08 | AB12: =+($D12-X12)^2/X12 -> -0.0001840871 | AC12: =+($E12-Y12)^2/Y12 -> 7.5164009e-08
A13: =1+A12 -> 9 | B13: =+COUNTIF(desglose!F:F,'pruebas de bondad de ajuste'!$A13) -> 0 | C13: =+COUNTIF(desglose!G:G,'pruebas de bondad de ajuste'!$A13) -> 0 | D13: =+COUNTIF(desglose!Q:Q,'pruebas de bondad de ajuste'!$A13)/'estadísticos descriptivos'!D$2 -> 0 | E13: =+COUNTIF(desglose!R:R,'pruebas de bondad de ajuste'!$A13)/'estadísticos descriptivos'!E$2 -> 0 | F13: =+_xlfn.POISSON.DIST($A13,'estadísticos descriptivos'!B$6,0)*'estadísticos descriptivos'!B$2 -> 0.033717382 | G13: =+_xlfn.POISSON.DIST($A13,'estadísticos descriptivos'!C$6,0)*'estadísticos descriptivos'!C$2 -> 3.0646984e-08 | H13: =+_xlfn.POISSON.DIST($A13,'estadísticos descriptivos'!D$6,0)*'estadísticos descriptivos'!D$2 -> 0.002296324 | I13: =+_xlfn.POISSON.DIST($A13,'estadísticos descriptivos'!E$6,0)*'estadísticos descriptivos'!E$2 -> 1.2879232e-06 | J13: =+($B13-F13)^2/F13 -> 0.033717382 | K13: =+($C13-G13)^2/G13 -> 3.0646984e-08 | L13: =+($D13-H13)^2/H13 -> 0.002296324 | M13: =+($E13-I13)^2/I13 -> 1.2879232e-06 | N13: =BINOMDIST($A13,90,'estadísticos descriptivos'!B$6/90,0)*'estadísticos descriptivos'!B$2 -> 0.027830306 | O13: =BINOMDIST($A13,90,'estadísticos descriptivos'!C$6/90,0)*'estadísticos descriptivos'!C$2 -> 2.1141739e-08 | P13: =BINOMDIST($A13,90,'estadísticos descriptivos'!D$6/90,0)*'estadísticos descriptivos'!D$2 -> 0.0018019772 | Q13: =BINOMDIST($A13,90,'estadísticos descriptivos'!E$6/90,0)*'estadísticos descriptivos'!E$2 -> 9.1339241e-07 | R13: =+($B13-N13)^2/N13 -> 0.027830306 | S13: =+($C13-O13)^2/O13 -> 2.1141739e-08 | T13: =+($D13-P13)^2/P13 -> 0.0018019772 | U13: =+($E13-Q13)^2/Q13 -> 9.1339241e-07 | V13: =+($A13+AD$1)/(($A13+1)*(1+AD$2))*V12 -> 0.0034613327 | W13: =+($A13+AE$1)/(($A13+1)*(1+AE$2))*W12 -> 2.2565265e-09 | X13: =+($A13+AF$1)/(($A13+1)*(1+AF$2))*X12 -> 0.00010074375 | Y13: =+($A13+AG$1)/(($A13+1)*(1+AG$2))*Y12 -> 1.8561235e-09 | Z13: =+($B13-V13)^2/V13 -> 0.0034613327 | AA13: =+($C13-W13)^2/W13 -> 2.2565265e-09 | AB13: =+($D13-X13)^2/X13 -> 0.00010074375 | AC13: =+($E13-Y13)^2/Y13 -> 1.8561235e-09
A14: =1+A13 -> 10 | B14: =+COUNTIF(desglose!F:F,'pruebas de bondad de ajuste'!$A14) -> 0 | C14: =+COUNTIF(desglose!G:G,'pruebas de bondad de ajuste'!$A14) -> 0 | D14: =+COUNTIF(desglose!Q:Q,'pruebas de bondad de ajuste'!$A14)/'estadísticos descriptivos'!D$2 -> 0 | E14: =+COUNTIF(desglose!R:R,'pruebas de bondad de ajuste'!$A14)/'estadísticos descriptivos'!E$2 -> 0 | F14: =+_xlfn.POISSON.DIST($A14,'estadísticos descriptivos'!B$6,0)*'estadísticos descriptivos'!B$2 -> 0.0085738486 | G14: =+_xlfn.POISSON.DIST($A14,'estadísticos descriptivos'!C$6,0)*'estadísticos descriptivos'!C$2 -> 1.3134422e-09 | H14: =+_xlfn.POISSON.DIST($A14,'estadísticos descriptivos'!D$6,0)*'estadísticos descriptivos'!D$2 -> 0.00043375008 | I14: =+_xlfn.POISSON.DIST($A14,'estadísticos descriptivos'!E$6,0)*'estadísticos descriptivos'!E$2 -> 9.3016677e-08 | J14: =+($B14-F14)^2/F14 -> 0.0085738486 | K14: =+($C14-G14)^2/G14 -> 1.3134422e-09 | L14: =+($D14-H14)^2/H14 -> 0.00043375008 | M14: =+($E14-I14)^2/I14 -> 9.3016677e-08 | N14: =BINOMDIST($A14,90,'estadísticos descriptivos'!B$6/90,0)*'estadísticos descriptivos'!B$2 -> 0.0065543507 | O14: =BINOMDIST($A14,90,'estadísticos descriptivos'!C$6/90,0)*'estadísticos descriptivos'!C$2 -> 8.1936884e-10 | P14: =BINOMDIST($A14,90,'estadísticos descriptivos'!D$6/90,0)*'estadísticos descriptivos'!D$2 -> 0.00031290323 | Q14: =BINOMDIST($A14,90,'estadísticos descriptivos'!E$6/90,0)*'estadísticos descriptivos'!E$2 -> 5.9850791e-08 | R14: =+($B14-N14)^2/N14 -> 0.0065543507 | S14: =+($C14-O14)^2/O14 -> 8.1936884e-10 | T14: =+($D14-P14)^2/P14 -> 0.00031290323 | U14: =+($E14-Q14)^2/Q14 -> 5.9850791e-08 | V14: =+($A14+AD$1)/(($A14+1)*(1+AD$2))*V13 -> 0.00080633949 | W14: =+($A14+AE$1)/(($A14+1)*(1+AE$2))*W13 -> 8.7916619e-11 | X14: =+($A14+AF$1)/(($A14+1)*(1+AF$2))*X13 -> -5.9602062e-05 | Y14: =+($A14+AG$1)/(($A14+1)*(1+AG$2))*Y13 -> 3.1980475e-11 | Z14: =+($B14-V14)^2/V14 -> 0.00080633949 | AA14: =+($C14-W14)^2/W14 -> 8.7916619e-11 | AB14: =+($D14-X14)^2/X14 -> -5.9602062e-05 | AC14: =+($E14-Y14)^2/Y14 -> 3.1980475e-11
A15: =1+A14 -> 11 | B15: =+COUNTIF(desglose!F:F,'pruebas de bondad de ajuste'!$A15) -> 0 | C15: =+COUNTIF(desglose!G:G,'pruebas de bondad de ajuste'!$A15) -> 0 | D15: =+COUNTIF(desglose!Q:Q,'pruebas de bondad de ajuste'!$A15)/'estadísticos descriptivos'!D$2 -> 0 | E15: =+COUNTIF(desglose!R:R,'pruebas de bondad de ajuste'!$A15)/'estadísticos descriptivos'!E$2 -> 0 | F15: =+_xlfn.POISSON.DIST($A15,'estadísticos descriptivos'!B$6,0)*'estadísticos descriptivos'!B$2 -> 0.0019820066 | G15: =+_xlfn.POISSON.DIST($A15,'estadísticos descriptivos'!C$6,0)*'estadísticos descriptivos'!C$2 -> 5.1173071e-11 | H15: =+_xlfn.POISSON.DIST($A15,'estadísticos descriptivos'!D$6,0)*'estadísticos descriptivos'!D$2 -> 7.4482337e-05 | I15: =+_xlfn.POISSON.DIST($A15,'estadísticos descriptivos'!E$6,0)*'estadísticos descriptivos'!E$2 -> 6.1071555e-09 | J15: =+($B15-F15)^2/F15 -> 0.0019820066 | K15: =+($C15-G15)^2/G15 -> 5.1173071e-11 | L15: =+($D15-H15)^2/H15 -> 7.4482337e-05 | M15: =+($E15-I15)^2/I15 -> 6.1071555e-09 | N15: =BINOMDIST($A15,90,'estadísticos descriptivos'!B$6/90,0)*'estadísticos descriptivos'!B$2 -> 0.0013859694 | O15: =BINOMDIST($A15,90,'estadísticos descriptivos'!C$6/90,0)*'estadísticos descriptivos'!C$2 -> 2.8512182e-11 | P15: =BINOMDIST($A15,90,'estadísticos descriptivos'!D$6/90,0)*'estadísticos descriptivos'!D$2 -> 4.8784637e-05 | Q15: =BINOMDIST($A15,90,'estadísticos descriptivos'!E$6/90,0)*'estadísticos descriptivos'!E$2 -> 3.5212323e-09 | R15: =+($B15-N15)^2/N15 -> 0.0013859694 | S15: =+($C15-O15)^2/O15 -> 2.8512182e-11 | T15: =+($D15-P15)^2/P15 -> 4.8784637e-05 | U15: =+($E15-Q15)^2/Q15 -> 3.5212323e-09 | V15: =+($A15+AD$1)/(($A15+1)*(1+AD$2))*V14 -> 0.0001723656 | W15: =+($A15+AE$1)/(($A15+1)*(1+AE$2))*W14 -> 3.1398792e-12 | X15: =+($A15+AF$1)/(($A15+1)*(1+AF$2))*X14 -> 3.7465041e-05 | Y15: =+($A15+AG$1)/(($A15+1)*(1+AG$2))*Y14 -> 3.5207993e-13 | Z15: =+($B15-V15)^2/V15 -> 0.0001723656 | AA15: =+($C15-W15)^2/W15 -> 3.1398792e-12 | AB15: =+($D15-X15)^2/X15 -> 3.7465041e-05 | AC15: =+($E15-Y15)^2/Y15 -> 3.5207993e-13
A16: =1+A15 -> 12 | B16: =+COUNTIF(desglose!F:F,'pruebas de bondad de ajuste'!$A16) -> 0 | C16: =+COUNTIF(desglose!G:G,'pruebas de bondad de ajuste'!$A16) -> 0 | D16: =+COUNTIF(desglose!Q:Q,'pruebas de bondad de ajuste'!$A16)/'estadísticos descriptivos'!D$2 -> 0 | E16: =+COUNTIF(desglose!R:R,'pruebas de bondad de ajuste'!$A16)/'estadísticos descriptivos'!E$2 -> 0 | F16: =+_xlfn.POISSON.DIST($A16,'estadísticos descriptivos'!B$6,0)*'estadísticos descriptivos'!B$2 -> 0.00041999663 | G16: =+_xlfn.POISSON.DIST($A16,'estadísticos descriptivos'!C$6,0)*'estadísticos descriptivos'!C$2 -> 1.8276097e-12 | H16: =+_xlfn.POISSON.DIST($A16,'estadísticos descriptivos'!D$6,0)*'estadísticos descriptivos'!D$2 -> 1.1724072e-05 | I16: =+_xlfn.POISSON.DIST($A16,'estadísticos descriptivos'!E$6,0)*'estadísticos descriptivos'!E$2 -> 3.6756029e-10 | J16: =+($B16-F16)^2/F16 -> 0.00041999663 | K16: =+($C16-G16)^2/G16 -> 1.8276097e-12 | L16: =+($D16-H16)^2/H16 -> 1.1724072e-05 | M16: =+($E16-I16)^2/I16 -> 3.6756029e-10 | N16: =BINOMDIST($A16,90,'estadísticos descriptivos'!B$6/90,0)*'estadísticos descriptivos'!B$2 -> 0.00026529323 | O16: =BINOMDIST($A16,90,'estadísticos descriptivos'!C$6/90,0)*'estadísticos descriptivos'!C$2 -> 8.98111e-13 | P16: =BINOMDIST($A16,90,'estadísticos descriptivos'!D$6/90,0)*'estadísticos descriptivos'!D$2 -> 6.8850113e-06 | Q16: =BINOMDIST($A16,90,'estadísticos descriptivos'!E$6/90,0)*'estadísticos descriptivos'!E$2 -> 1.8752881e-10 | R16: =+($B16-N16)^2/N16 -> 0.00026529323 | S16: =+($C16-O16)^2/O16 -> 8.98111e-13 | T16: =+($D16-P16)^2/P16 -> 6.8850113e-06 | U16: =+($E16-Q16)^2/Q16 -> 1.8752881e-10 | V16: =+($A16+AD$1)/(($A16+1)*(1+AD$2))*V15 -> 3.4046099e-05 | W16: =+($A16+AE$1)/(($A16+1)*(1+AE$2))*W15 -> 1.035125e-13 | X16: =+($A16+AF$1)/(($A16+1)*(1+AF$2))*X15 -> -2.4721876e-05 | Y16: =+($A16+AG$1)/(($A16+1)*(1+AG$2))*Y15 -> 2.0229514e-15 | Z16: =+($B16-V16)^2/V16 -> 3.4046099e-05 | AA16: =+($C16-W16)^2/W16 -> 1.035125e-13 | AB16: =+($D16-X16)^2/X16 -> -2.4721876e-05 | AC16: =+($E16-Y16)^2/Y16 -> 2.0229514e-15
A17: =1+A16 -> 13 | B17: =+COUNTIF(desglose!F:F,'pruebas de bondad de ajuste'!$A17) -> 0 | C17: =+COUNTIF(desglose!G:G,'pruebas de bondad de ajuste'!$A17) -> 0 | D17: =+COUNTIF(desglose!Q:Q,'pruebas de bondad de ajuste'!$A17)/'estadísticos descriptivos'!D$2 -> 0 | E17: =+COUNTIF(desglose!R:R,'pruebas de bondad de ajuste'!$A17)/'estadísticos descriptivos'!E$2 -> 0 | F17: =+_xlfn.POISSON.DIST($A17,'estadísticos descriptivos'!B$6,0)*'estadísticos descriptivos'!B$2 -> 8.2153186e-05 | G17: =+_xlfn.POISSON.DIST($A17,'estadísticos descriptivos'!C$6,0)*'estadísticos descriptivos'!C$2 -> 6.0250869e-14 | H17: =+_xlfn.POISSON.DIST($A17,'estadísticos descriptivos'!D$6,0)*'estadísticos descriptivos'!D$2 -> 1.7034976e-06 | I17: =+_xlfn.POISSON.DIST($A17,'estadísticos descriptivos'!E$6,0)*'estadísticos descriptivos'!E$2 -> 2.0420016e-11 | J17: =+($B17-F17)^2/F17 -> 8.2153186e-05 | K17: =+($C17-G17)^2/G17 -> 6.0250869e-14 | L17: =+($D17-H17)^2/H17 -> 1.7034976e-06 | M17: =+($E17-I17)^2/I17 -> 2.0420016e-11 | N17: =BINOMDIST($A17,90,'estadísticos descriptivos'!B$6/90,0)*'estadísticos descriptivos'!B$2 -> 4.6281146e-05 | O17: =BINOMDIST($A17,90,'estadísticos descriptivos'!C$6/90,0)*'estadísticos descriptivos'!C$2 -> 2.5783091e-14 | P17: =BINOMDIST($A17,90,'estadísticos descriptivos'!D$6/90,0)*'estadísticos descriptivos'!D$2 -> 8.8558783e-07 | Q17: =BINOMDIST($A17,90,'estadísticos descriptivos'!E$6/90,0)*'estadísticos descriptivos'!E$2 -> 9.1022072e-12 | R17: =+($B17-N17)^2/N17 -> 4.6281146e-05 | S17: =+($C17-O17)^2/O17 -> 2.5783091e-14 | T17: =+($D17-P17)^2/P17 -> 8.8558783e-07 | U17: =+($E17-Q17)^2/Q17 -> 9.1022072e-12 | V17: =+($A17+AD$1)/(($A17+1)*(1+AD$2))*V16 -> 6.2509376e-06 | W17: =+($A17+AE$1)/(($A17+1)*(1+AE$2))*W16 -> 3.1687501e-15 | X17: =+($A17+AF$1)/(($A17+1)*(1+AF$2))*X16 -> 1.6975909e-05 | Y17: =+($A17+AG$1)/(($A17+1)*(1+AG$2))*Y16 -> 2.4966173e-18 | Z17: =+($B17-V17)^2/V17 -> 6.2509376e-06 | AA17: =+($C17-W17)^2/W17 -> 3.1687501e-15 | AB17: =+($D17-X17)^2/X17 -> 1.6975909e-05 | AC17: =+($E17-Y17)^2/Y17 -> 2.4966173e-18
... A94: =1+A93 -> 90 | B94: =+COUNTIF(desglose!F:F,'pruebas de bondad de ajuste'!$A94) -> 0 | C94: =+COUNTIF(desglose!G:G,'pruebas de bondad de ajuste'!$A94) -> 0 | D94: =+COUNTIF(desglose!Q:Q,'pruebas de bondad de ajuste'!$A94)/'estadísticos descriptivos'!D$2 -> 0 | E94: =+COUNTIF(desglose!R:R,'pruebas de bondad de ajuste'!$A94)/'estadísticos descriptivos'!E$2 -> 0 | F94: =+_xlfn.POISSON.DIST($A94,'estadísticos descriptivos'!B$6,0)*'estadísticos descriptivos'!B$2 -> 5.581617e-102 | G94: =+_xlfn.POISSON.DIST($A94,'estadísticos descriptivos'!C$6,0)*'estadísticos descriptivos'!C$2 -> 1.1697562e-170 | H94: =+_xlfn.POISSON.DIST($A94,'estadísticos descriptivos'!D$6,0)*'estadísticos descriptivos'!D$2 -> 1.3230607e-113 | I94: =+_xlfn.POISSON.DIST($A94,'estadísticos descriptivos'!E$6,0)*'estadísticos descriptivos'!E$2 -> 1.1221627e-150 | J94: =+($B94-F94)^2/F94 -> 5.581617e-102 | K94: =+($C94-G94)^2/G94 -> 0 | L94: =+($D94-H94)^2/H94 -> 1.3230607e-113 | M94: =+($E94-I94)^2/I94 -> 1.1221627e-150 | N94: =BINOMDIST($A94,90,'estadísticos descriptivos'!B$6/90,0)*'estadísticos descriptivos'!B$2 -> 1.3842636e-138 | O94: =BINOMDIST($A94,90,'estadísticos descriptivos'!C$6/90,0)*'estadísticos descriptivos'!C$2 -> 3.502124e-208 | P94: =BINOMDIST($A94,90,'estadísticos descriptivos'!D$6/90,0)*'estadísticos descriptivos'!D$2 -> 1.7061756e-150 | Q94: =BINOMDIST($A94,90,'estadísticos descriptivos'!E$6/90,0)*'estadísticos descriptivos'!E$2 -> 4.5063291e-188 | R94: =+($B94-N94)^2/N94 -> 1.3842636e-138 | S94: =+($C94-O94)^2/O94 -> 0 | T94: =+($D94-P94)^2/P94 -> 1.7061756e-150 | U94: =+($E94-Q94)^2/Q94 -> 0 | V94: =+($A94+AD$1)/(($A94+1)*(1+AD$2))*V93 -> 3.0169676e-102 | W94: =+($A94+AE$1)/(($A94+1)*(1+AE$2))*W93 -> 9.4646964e-173 | X94: =+($A94+AF$1)/(($A94+1)*(1+AF$2))*X93 -> -1.9685073e-08 | Y94: =+($A94+AG$1)/(($A94+1)*(1+AG$2))*Y93 -> -1.3561885e-130 | Z94: =+($B94-V94)^2/V94 -> 3.0169676e-102 | AA94: =+($C94-W94)^2/W94 -> 0 | AB94: =+($D94-X94)^2/X94 -> -1.9685073e-08 | AC94: =+($E94-Y94)^2/Y94 -> -1.3561885e-130

Sheet sumario distribuciones elegidas
B1: GF-local | C1: GA-local | D1: GF-visitante | E1: GA-visitante | O1: F(GF-local) | P1: F(GA-local) | Q1: F(GF-visitante) | R1: F(GA-visitante) | S1: goles
A2: media < varianza | B2: =+IF('estadísticos descriptivos'!B6<'estadísticos descriptivos'!B7,1,0) -> 1 | C2: =+IF('estadísticos descriptivos'!C6<'estadísticos descriptivos'!C7,1,0) -> 0 | D2: =+IF('estadísticos descriptivos'!D6<'estadísticos descriptivos'!D7,1,0) -> 0 | E2: =+IF('estadísticos descriptivos'!E6<'estadísticos descriptivos'!E7,1,0) -> 0 | H2: goles | I2: F(GF-local) | J2: F(GA-local) | K2: F(GF-visitante) | L2: F(GA-visitante) | N2: goles | O2: 0 | P2: 0 | Q2: 0 | R2: 0 | S2: 0
A3: media > varianza | B3: =1-B2 -> 0 | C3: =1-C2 -> 1 | D3: =1-D2 -> 1 | E3: =1-E2 -> 1 | H3: 0 | I3: =+IF(B$8="binomial",_xlfn.BINOM.DIST($H3,B$9,B$10,0),IF(B$8="Binomial negativa",(B$10/(1+B$10))^B$9,_xlfn.POISSON.DIST($H3,B$9,0))) -> 0.078641389 | J3: =+IF(C$8="binomial",_xlfn.BINOM.DIST($H3,C$9,C$10,0),IF(C$8="Binomial negativa",(C$10/(1+C$10))^C$9,_xlfn.POISSON.DIST($H3,C$9,0))) -> 0.65143906 | K3: =+IF(D$8="binomial",_xlfn.BINOM.DIST($H3,D$9,D$10,0),IF(D$8="Binomial negativa",(D$10/(1+D$10))^D$9,_xlfn.POISSON.DIST($H3,D$9,0))) -> 0.14822968 | L3: =+IF(E$8="binomial",_xlfn.BINOM.DIST($H3,E$9,E$10,0),IF(E$8="Binomial negativa",(E$10/(1+E$10))^E$9,_xlfn.POISSON.DIST($H3,E$9,0))) -> 0.48567179 | N3: 0 | O3: =+I3 -> 0.078641389 | P3: =+J3 -> 0.65143906 | Q3: =+K3 -> 0.14822968 | R3: =+L3 -> 0.48567179 | S3: =1+S2 -> 1
A4: diferencia relativa | B4: =+'estadísticos descriptivos'!B8 -> 0.0026437541 | C4: =+'estadísticos descriptivos'!C8 -> 1.2952602e-16 | D4: =+'estadísticos descriptivos'!D8 -> 1.0352113 | E4: =+'estadísticos descriptivos'!E8 -> 0.057416268 | H4: =1+H3 -> 1 | I4: =+IF(B$8="binomial",_xlfn.BINOM.DIST($H4,B$9,B$10,0),IF(B$8="Binomial negativa",((1+(B$9-1)/$H4)/(1+B$10))*I3,_xlfn.POISSON.DIST($H4,B$9,0))) -> 0.19997382 | J4: =+IF(C$8="binomial",_xlfn.BINOM.DIST($H4,C$9,C$10,0),IF(C$8="Binomial negativa",((1+(C$9-1)/$H4)/(1+C$10))*J3,_xlfn.POISSON.DIST($H4,C$9,0))) -> 0.27918817 | K4: =+IF(D$8="binomial",_xlfn.BINOM.DIST($H4,D$9,D$10,0),IF(D$8="Binomial negativa",((1+(D$9-1)/$H4)/(1+D$10))*K3,_xlfn.POISSON.DIST($H4,D$9,0))) -> 0.28599168 | L4: =+IF(E$8="binomial",_xlfn.BINOM.DIST($H4,E$9,E$10,0),IF(E$8="Binomial negativa",((1+(E$9-1)/$H4)/(1+E$10))*L3,_xlfn.POISSON.DIST($H4,E$9,0))) -> 0.35076296 | N4: =1+N3 -> 1 | O4: =+O3+I4 -> 0.27861521 | P4: =+P3+J4 -> 0.93062723 | Q4: =+Q3+K4 -> 0.43422136 | R4: =+R3+L4 -> 0.83643474 | S4: =1+S3 -> 2
A5: poisson | B5: =+IF(AND(B4<=10%,'pruebas de bondad de ajuste'!J3="no rechazar"),1,0) -> 1 | C5: =+IF(AND(C4<=10%,'pruebas de bondad de ajuste'!K3="no rechazar"),1,0) -> 1 | D5: =+IF(AND(D4<=10%,'pruebas de bondad de ajuste'!L3="no rechazar"),1,0) -> 0 | E5: =+IF(AND(E4<=10%,'pruebas de bondad de ajuste'!M3="no rechazar"),1,0) -> 1 | F5: poisson | H5: =1+H4 -> 2 | I5: =+IF(B$8="binomial",_xlfn.BINOM.DIST($H5,B$9,B$10,0),IF(B$8="Binomial negativa",((1+(B$9-1)/$H5)/(1+B$10))*I4,_xlfn.POISSON.DIST($H5,B$9,0))) -> 0.25425242 | J5: =+IF(C$8="binomial",_xlfn.BINOM.DIST($H5,C$9,C$10,0),IF(C$8="Binomial negativa",((1+(C$9-1)/$H5)/(1+C$10))*J4,_xlfn.POISSON.DIST($H5,C$9,0))) -> 0.059826036 | K5: =+IF(D$8="binomial",_xlfn.BINOM.DIST($H5,D$9,D$10,0),IF(D$8="Binomial negativa",((1+(D$9-1)/$H5)/(1+D$10))*K4,_xlfn.POISSON.DIST($H5,D$9,0))) -> 0.27282813 | L5: =+IF(E$8="binomial",_xlfn.BINOM.DIST($H5,E$9,E$10,0),IF(E$8="Binomial negativa",((1+(E$9-1)/$H5)/(1+E$10))*L4,_xlfn.POISSON.DIST($H5,E$9,0))) -> 0.1266644 | N5: =1+N4 -> 2 | O5: =+O4+I5 -> 0.53286763 | P5: =+P4+J5 -> 0.99045326 | Q5: =+Q4+K5 -> 0.70704949 | R5: =+R4+L5 -> 0.96309914 | S5: =1+S4 -> 3
A6: binomial | B6: =+IF(AND(B3=1,'pruebas de bondad de ajuste'!R3="no rechazar"),1,0) -> 0 | C6: =+IF(AND(C3=1,'pruebas de bondad de ajuste'!S3="no rechazar"),1,0) -> 1 | D6: =+IF(AND(D3=1,'pruebas de bondad de ajuste'!T3="no rechazar"),1,0) -> 1 | E6: =+IF(AND(E3=1,'pruebas de bondad de ajuste'!U3="no rechazar"),1,0) -> 1 | F6: binomial | H6: =1+H5 -> 3 | I6: =+IF(B$8="binomial",_xlfn.BINOM.DIST($H6,B$9,B$10,0),IF(B$8="Binomial negativa",((1+(B$9-1)/$H6)/(1+B$10))*I5,_xlfn.POISSON.DIST($H6,B$9,0))) -> 0.2155092 | J6: =+IF(C$8="binomial",_xlfn.BINOM.DIST($H6,C$9,C$10,0),IF(C$8="Binomial negativa",((1+(C$9-1)/$H6)/(1+C$10))*J5,_xlfn.POISSON.DIST($H6,C$9,0))) -> 0.0085465766 | K6: =+IF(D$8="binomial",_xlfn.BINOM.DIST($H6,D$9,D$10,0),IF(D$8="Binomial negativa",((1+(D$9-1)/$H6)/(1+D$10))*K5,_xlfn.POISSON.DIST($H6,D$9,0))) -> 0.17156405 | L6: =+IF(E$8="binomial",_xlfn.BINOM.DIST($H6,E$9,E$10,0),IF(E$8="Binomial negativa",((1+(E$9-1)/$H6)/(1+E$10))*L5,_xlfn.POISSON.DIST($H6,E$9,0))) -> 0.030493282 | N6: =1+N5 -> 3 | O6: =+O5+I6 -> 0.74837683 | P6: =+P5+J6 -> 0.99899984 | Q6: =+Q5+K6 -> 0.87861354 | R6: =+R5+L6 -> 0.99359242 | S6: =1+S5 -> 4
A7: Binomial negativa | B7: =+IF(AND(B2=1,'pruebas de bondad de ajuste'!Z3="no rechazar"),1,0) -> 1 | C7: =+IF(AND(C2=1,'pruebas de bondad de ajuste'!AA3="no rechazar"),1,0) -> 0 | D7: =+IF(AND(D2=1,'pruebas de bondad de ajuste'!AB3="no rechazar"),1,0) -> 0 | E7: =+IF(AND(E2=1,'pruebas de bondad de ajuste'!AC3="no rechazar"),1,0) -> 0 | F7: Binomial negativa | H7: =1+H6 -> 4 | I7: =+IF(B$8="binomial",_xlfn.BINOM.DIST($H7,B$9,B$10,0),IF(B$8="Binomial negativa",((1+(B$9-1)/$H7)/(1+B$10))*I6,_xlfn.POISSON.DIST($H7,B$9,0))) -> 0.13700228 | J7: =+IF(C$8="binomial",_xlfn.BINOM.DIST($H7,C$9,C$10,0),IF(C$8="Binomial negativa",((1+(C$9-1)/$H7)/(1+C$10))*J6,_xlfn.POISSON.DIST($H7,C$9,0))) -> 0.00091570463 | K7: =+IF(D$8="binomial",_xlfn.BINOM.DIST($H7,D$9,D$10,0),IF(D$8="Binomial negativa",((1+(D$9-1)/$H7)/(1+D$10))*K6,_xlfn.POISSON.DIST($H7,D$9,0))) -> 0.079994715 | L7: =+IF(E$8="binomial",_xlfn.BINOM.DIST($H7,E$9,E$10,0),IF(E$8="Binomial negativa",((1+(E$9-1)/$H7)/(1+E$10))*L6,_xlfn.POISSON.DIST($H7,E$9,0))) -> 0.0055057314 | N7: =1+N6 -> 4 | O7: =+O6+I7 -> 0.88537911 | P7: =+P6+J7 -> 0.99991554 | Q7: =+Q6+K7 -> 0.95860826 | R7: =+R6+L7 -> 0.99909816 | S7: =1+S6 -> 5
A8: distribución | B8: =+VLOOKUP(1,B5:$F$7,5,0) -> poisson | C8: =+VLOOKUP(1,C5:$F$7,4,0) -> poisson | D8: =+VLOOKUP(1,D5:$F$7,3,0) -> binomial | E8: =+VLOOKUP(1,E5:$F$7,2,0) -> poisson | H8: =1+H7 -> 5 | I8: =+IF(B$8="binomial",_xlfn.BINOM.DIST($H8,B$9,B$10,0),IF(B$8="Binomial negativa",((1+(B$9-1)/$H8)/(1+B$10))*I7,_xlfn.POISSON.DIST($H8,B$9,0))) -> 0.069675443 | J8: =+IF(C$8="binomial",_xlfn.BINOM.DIST($H8,C$9,C$10,0),IF(C$8="Binomial negativa",((1+(C$9-1)/$H8)/(1+C$10))*J7,_xlfn.POISSON.DIST($H8,C$9,0))) -> 7.8488968e-05 | K8: =+IF(D$8="binomial",_xlfn.BINOM.DIST($H8,D$9,D$10,0),IF(D$8="Binomial negativa",((1+(D$9-1)/$H8)/(1+D$10))*K7,_xlfn.POISSON.DIST($H8,D$9,0))) -> 0.02949616 | L8: =+IF(E$8="binomial",_xlfn.BINOM.DIST($H8,E$9,E$10,0),IF(E$8="Binomial negativa",((1+(E$9-1)/$H8)/(1+E$10))*L7,_xlfn.POISSON.DIST($H8,E$9,0))) -> 0.00079527232 | N8: =1+N7 -> 5 | O8: =+O7+I8 -> 0.95505455 | P8: =+P7+J8 -> 0.99999403 | Q8: =+Q7+K8 -> 0.98810442 | R8: =+R7+L8 -> 0.99989343 | S8: =1+S7 -> 6
A9: parámetro 1 | B9: =+IF(B8="binomial",90,IF('sumario distribuciones elegidas'!B8="poisson",'estadísticos descriptivos'!B6,'pruebas de bondad de ajuste'!AD1)) -> 2.5428571 | C9: =+IF(C8="binomial",90,IF('sumario distribuciones elegidas'!C8="poisson",'estadísticos descriptivos'!C6,'pruebas de bondad de ajuste'!AE1)) -> 0.42857143 | D9: =+IF(D8="binomial",90,IF('sumario distribuciones elegidas'!D8="poisson",'estadísticos descriptivos'!D6,'pruebas de bondad de ajuste'!AF1)) -> 90 | E9: =+IF(E8="binomial",90,IF('sumario distribuciones elegidas'!E8="poisson",'estadísticos descriptivos'!E6,'pruebas de bondad de ajuste'!AG1)) -> 0.72222222 | H9: =1+H8 -> 6 | I9: =+IF(B$8="binomial",_xlfn.BINOM.DIST($H9,B$9,B$10,0),IF(B$8="Binomial negativa",((1+(B$9-1)/$H9)/(1+B$10))*I8,_xlfn.POISSON.DIST($H9,B$9,0))) -> 0.029529116 | J9: =+IF(C$8="binomial",_xlfn.BINOM.DIST($H9,C$9,C$10,0),IF(C$8="Binomial negativa",((1+(C$9-1)/$H9)/(1+C$10))*J8,_xlfn.POISSON.DIST($H9,C$9,0))) -> 5.6063549e-06 | K9: =+IF(D$8="binomial",_xlfn.BINOM.DIST($H9,D$9,D$10,0),IF(D$8="Binomial negativa",((1+(D$9-1)/$H9)/(1+D$10))*K8,_xlfn.POISSON.DIST($H9,D$9,0))) -> 0.0089579552 | L9: =+IF(E$8="binomial",_xlfn.BINOM.DIST($H9,E$9,E$10,0),IF(E$8="Binomial negativa",((1+(E$9-1)/$H9)/(1+E$10))*L8,_xlfn.POISSON.DIST($H9,E$9,0))) -> 9.5727223e-05 | N9: =1+N8 -> 6 | O9: =+O8+I9 -> 0.98458366 | P9: =+P8+J9 -> 0.99999964 | Q9: =+Q8+K9 -> 0.99706237 | R9: =+R8+L9 -> 0.99998915 | S9: =1+S8 -> 7
A10: parámetro 2 | B10: =+IF(B8="binomial",'estadísticos descriptivos'!B6/90,IF('sumario distribuciones elegidas'!B8="poisson",0,'pruebas de bondad de ajuste'!AD2)) -> 0 | C10: =+IF(C8="binomial",'estadísticos descriptivos'!C6/90,IF('sumario distribuciones elegidas'!C8="poisson",0,'pruebas de bondad de ajuste'!AE2)) -> 0 | D10: =+IF(D8="binomial",'estadísticos descriptivos'!D6/90,IF('sumario distribuciones elegidas'!D8="poisson",0,'pruebas de bondad de ajuste'!AF2)) -> 0.020987654 | E10: =+IF(E8="binomial",'estadísticos descriptivos'!E6/90,IF('sumario distribuciones elegidas'!E8="poisson",0,'pruebas de bondad de ajuste'!AG2)) -> 0 | H10: =1+H9 -> 7 | I10: =+IF(B$8="binomial",_xlfn.BINOM.DIST($H10,B$9,B$10,0),IF(B$8="Binomial negativa",((1+(B$9-1)/$H10)/(1+B$10))*I9,_xlfn.POISSON.DIST($H10,B$9,0))) -> 0.010726904 | J10: =+IF(C$8="binomial",_xlfn.BINOM.DIST($H10,C$9,C$10,0),IF(C$8="Binomial negativa",((1+(C$9-1)/$H10)/(1+C$10))*J9,_xlfn.POISSON.DIST($H10,C$9,0))) -> 3.4324622e-07 | K10: =+IF(D$8="binomial",_xlfn.BINOM.DIST($H10,D$9,D$10,0),IF(D$8="Binomial negativa",((1+(D$9-1)/$H10)/(1+D$10))*K9,_xlfn.POISSON.DIST($H10,D$9,0))) -> 0.0023044424 | L10: =+IF(E$8="binomial",_xlfn.BINOM.DIST($H10,E$9,E$10,0),IF(E$8="Binomial negativa",((1+(E$9-1)/$H10)/(1+E$10))*L9,_xlfn.POISSON.DIST($H10,E$9,0))) -> 9.8766183e-06 | N10: =1+N9 -> 7 | O10: =+O9+I10 -> 0.99531057 | P10: =+P9+J10 -> 0.99999998 | Q10: =+Q9+K10 -> 0.99936682 | R10: =+R9+L10 -> 0.99999903 | S10: =1+S9 -> 8
H11: =1+H10 -> 8 | I11: =+IF(B$8="binomial",_xlfn.BINOM.DIST($H11,B$9,B$10,0),IF(B$8="Binomial negativa",((1+(B$9-1)/$H11)/(1+B$10))*I10,_xlfn.POISSON.DIST($H11,B$9,0))) -> 0.0034096229 | J11: =+IF(C$8="binomial",_xlfn.BINOM.DIST($H11,C$9,C$10,0),IF(C$8="Binomial negativa",((1+(C$9-1)/$H11)/(1+C$10))*J10,_xlfn.POISSON.DIST($H11,C$9,0))) -> 1.838819e-08 | K11: =+IF(D$8="binomial",_xlfn.BINOM.DIST($H11,D$9,D$10,0),IF(D$8="Binomial negativa",((1+(D$9-1)/$H11)/(1+D$10))*K10,_xlfn.POISSON.DIST($H11,D$9,0))) -> 0.00051254229 | L11: =+IF(E$8="binomial",_xlfn.BINOM.DIST($H11,E$9,E$10,0),IF(E$8="Binomial negativa",((1+(E$9-1)/$H11)/(1+E$10))*L10,_xlfn.POISSON.DIST($H11,E$9,0))) -> 8.9163915e-07 | N11: =1+N10 -> 8 | O11: =+O10+I11 -> 0.99872019 | P11: =+P10+J11 -> 1 | Q11: =+Q10+K11 -> 0.99987936 | R11: =+R10+L11 -> 0.99999992 | S11: =1+S10 -> 9
